RPC_ERROR
Odoo Server Error
Traceback (most recent call last):
  File "C:\Program Files\Odoo 16.0.20221031\server\odoo\http.py", line 1583, in _serve_db
    return service_model.retrying(self._serve_ir_http, self.env)
  File "C:\Program Files\Odoo 16.0.20221031\server\odoo\service\model.py", line 134, in retrying
    result = func()
  File "C:\Program Files\Odoo 16.0.20221031\server\odoo\http.py", line 1610, in _serve_ir_http
    response = self.dispatcher.dispatch(rule.endpoint, args)
  File "C:\Program Files\Odoo 16.0.20221031\server\odoo\http.py", line 1808, in dispatch
    result = self.request.registry['ir.http']._dispatch(endpoint)
  File "C:\Program Files\Odoo 16.0.20221031\server\odoo\addons\website\models\ir_http.py", line 235, in _dispatch
    response = super()._dispatch(endpoint)
  File "C:\Program Files\Odoo 16.0.20221031\server\odoo\addons\base\models\ir_http.py", line 154, in _dispatch
    result = endpoint(**request.params)
  File "C:\Program Files\Odoo 16.0.20221031\server\odoo\http.py", line 696, in route_wrapper
    result = endpoint(self, *args, **params_ok)
  File "C:\Program Files\Odoo 16.0.20221031\server\odoo\addons\web\controllers\dataset.py", line 42, in call_kw
    return self._call_kw(model, method, args, kwargs)
  File "C:\Program Files\Odoo 16.0.20221031\server\odoo\addons\web\controllers\dataset.py", line 33, in _call_kw
    return call_kw(request.env[model], method, args, kwargs)
  File "C:\Program Files\Odoo 16.0.20221031\server\odoo\api.py", line 457, in call_kw
    result = _call_kw_model(method, model, args, kwargs)
  File "C:\Program Files\Odoo 16.0.20221031\server\odoo\api.py", line 430, in _call_kw_model
    result = method(recs, *args, **kwargs)
  File "C:\Program Files\Odoo 16.0.20221031\server\odoo\addons\web\models\models.py", line 62, in web_search_read
    records = self.search_read(domain, fields, offset=offset, limit=limit, order=order)
  File "C:\Program Files\Odoo 16.0.20221031\server\odoo\models.py", line 4985, in search_read
    result = records.read(fields, **read_kwargs)
  File "C:\Program Files\Odoo 16.0.20221031\server\odoo\models.py", line 2968, in read
    raise ValueError("Invalid field %r on model %r" % (name, self._name))
ValueError: Invalid field 'startdate' on model 'gmcmodule.employeetable'

The above server error caused the following client error:
OwlError: The following error occurred in onWillStart: "Odoo Server Error"
    at wrapError (http://localhost:8069/web/assets/276-994b0b0/web.assets_common.min.js:1592:77)
    at onWillStart (http://localhost:8069/web/assets/276-994b0b0/web.assets_common.min.js:1598:117)
    at useModel (http://localhost:8069/web/assets/277-f0220e1/web.assets_backend.min.js:4772:1)
    at ListController.setup (http://localhost:8069/web/assets/277-f0220e1/web.assets_backend.min.js:4490:676)
    at new ComponentNode (http://localhost:8069/web/assets/276-994b0b0/web.assets_common.min.js:1553:202)
    at http://localhost:8069/web/assets/276-994b0b0/web.assets_common.min.js:2080:6
    at View.slot1 (eval at compile (http://localhost:8069/web/assets/276-994b0b0/web.assets_common.min.js:2045:370), <anonymous>:15:36)
    at callSlot (http://localhost:8069/web/assets/276-994b0b0/web.assets_common.min.js:1657:25)
    at WithSearch.template (eval at compile (http://localhost:8069/web/assets/276-994b0b0/web.assets_common.min.js:2045:370), <anonymous>:8:12)
    at Fiber._render (http://localhost:8069/web/assets/276-994b0b0/web.assets_common.min.js:1491:96)

Caused by: RPC_ERROR: Odoo Server Error
    at makeErrorFromResponse (http://localhost:8069/web/assets/277-f0220e1/web.assets_backend.min.js:970:163)
    at XMLHttpRequest.<anonymous> (http://localhost:8069/web/assets/277-f0220e1/web.assets_backend.min.js:978:13)